Workbook

Sheet Tổng quan
B2: BÁO CÁO TEST CASE — HỆ THỐNG TƯỚI TỰ ĐỘNG (LoRa Node ↔ Gateway ↔ Server)
B3: Thống kê theo nhóm test case — cập nhật cột 'Kết quả' ở sheet 'Test Cases'
B5: Nhóm | C5: Mô tả nhóm | D5: Tổng số TC | E5: Pass | F5: Fail | G5: Blocked | H5: Not run | I5: % Pass
B6: A | C6: Bootstrap (khởi động hệ thống) | D6: =COUNTIF('Test Cases'!$A$2:$A$46,B6) -> 4 | E6: =COUNTIFS('Test Cases'!$A$2:$A$46,B6,'Test Cases'!$K$2:$K$46,"Pass") -> 0 | F6: =COUNTIFS('Test Cases'!$A$2:$A$46,B6,'Test Cases'!$K$2:$K$46,"Fail") -> 0 | G6: =COUNTIFS('Test Cases'!$A$2:$A$46,B6,'Test Cases'!$K$2:$K$46,"Blocked") -> 0 | H6: =D6-E6-F6-G6 -> 4 | I6: =IF(D6=0,0,E6/D6) -> 0
B7: B | C7: Node → Gateway (LoRa uplink) | D7: =COUNTIF('Test Cases'!$A$2:$A$46,B7) -> 5 | E7: =COUNTIFS('Test Cases'!$A$2:$A$46,B7,'Test Cases'!$K$2:$K$46,"Pass") -> 0 | F7: =COUNTIFS('Test Cases'!$A$2:$A$46,B7,'Test Cases'!$K$2:$K$46,"Fail") -> 0 | G7: =COUNTIFS('Test Cases'!$A$2:$A$46,B7,'Test Cases'!$K$2:$K$46,"Blocked") -> 0 | H7: =D7-E7-F7-G7 -> 5 | I7: =IF(D7=0,0,E7/D7) -> 0
B8: C | C8: Gateway → Server (MQTT) | D8: =COUNTIF('Test Cases'!$A$2:$A$46,B8) -> 5 | E8: =COUNTIFS('Test Cases'!$A$2:$A$46,B8,'Test Cases'!$K$2:$K$46,"Pass") -> 0 | F8: =COUNTIFS('Test Cases'!$A$2:$A$46,B8,'Test Cases'!$K$2:$K$46,"Fail") -> 0 | G8: =COUNTIFS('Test Cases'!$A$2:$A$46,B8,'Test Cases'!$K$2:$K$46,"Blocked") -> 0 | H8: =D8-E8-F8-G8 -> 5 | I8: =IF(D8=0,0,E8/D8) -> 0
B9: D | C9: Server → Node (lệnh, end-to-end) | D9: =COUNTIF('Test Cases'!$A$2:$A$46,B9) -> 10 | E9: =COUNTIFS('Test Cases'!$A$2:$A$46,B9,'Test Cases'!$K$2:$K$46,"Pass") -> 0 | F9: =COUNTIFS('Test Cases'!$A$2:$A$46,B9,'Test Cases'!$K$2:$K$46,"Fail") -> 0 | G9: =COUNTIFS('Test Cases'!$A$2:$A$46,B9,'Test Cases'!$K$2:$K$46,"Blocked") -> 0 | H9: =D9-E9-F9-G9 -> 10 | I9: =IF(D9=0,0,E9/D9) -> 0
B10: E | C10: Node behaviors (hành vi node) | D10: =COUNTIF('Test Cases'!$A$2:$A$46,B10) -> 6 | E10: =COUNTIFS('Test Cases'!$A$2:$A$46,B10,'Test Cases'!$K$2:$K$46,"Pass") -> 0 | F10: =COUNTIFS('Test Cases'!$A$2:$A$46,B10,'Test Cases'!$K$2:$K$46,"Fail") -> 0 | G10: =COUNTIFS('Test Cases'!$A$2:$A$46,B10,'Test Cases'!$K$2:$K$46,"Blocked") -> 0 | H10: =D10-E10-F10-G10 -> 6 | I10: =IF(D10=0,0,E10/D10) -> 0
B11: F | C11: System test (end-to-end) | D11: =COUNTIF('Test Cases'!$A$2:$A$46,B11) -> 7 | E11: =COUNTIFS('Test Cases'!$A$2:$A$46,B11,'Test Cases'!$K$2:$K$46,"Pass") -> 0 | F11: =COUNTIFS('Test Cases'!$A$2:$A$46,B11,'Test Cases'!$K$2:$K$46,"Fail") -> 0 | G11: =COUNTIFS('Test Cases'!$A$2:$A$46,B11,'Test Cases'!$K$2:$K$46,"Blocked") -> 0 | H11: =D11-E11-F11-G11 -> 7 | I11: =IF(D11=0,0,E11/D11) -> 0
B12: G | C12: Negative / Edge cases | D12: =COUNTIF('Test Cases'!$A$2:$A$46,B12) -> 8 | E12: =COUNTIFS('Test Cases'!$A$2:$A$46,B12,'Test Cases'!$K$2:$K$46,"Pass") -> 0 | F12: =COUNTIFS('Test Cases'!$A$2:$A$46,B12,'Test Cases'!$K$2:$K$46,"Fail") -> 0 | G12: =COUNTIFS('Test Cases'!$A$2:$A$46,B12,'Test Cases'!$K$2:$K$46,"Blocked") -> 0 | H12: =D12-E12-F12-G12 -> 8 | I12: =IF(D12=0,0,E12/D12) -> 0
B13: TỔNG CỘNG | D13: =SUM(D6:D12) -> 45 | E13: =SUM(E6:E12) -> 0 | F13: =SUM(F6:F12) -> 0 | G13: =SUM(G6:G12) -> 0 | H13: =SUM(H6:H12) -> 45 | I13: =IF(D13=0,0,E13/D13) -> 0
B16: Ghi chú:
B17: - Cột 'Kết quả' ở sheet 'Test Cases' dùng dropdown: Pass / Fail / Blocked / Not run.
B18: - Bảng 'Tổng quan' tự động cập nhật theo dữ liệu đã điền (dùng công thức COUNTIFS).
B19: - Có thể lọc theo cột 'Nhóm', 'Loại', 'Tầng' bằng AutoFilter trên sheet 'Test Cases'.
B20: - CRC8 (XOR) mẫu và bảng verify tool tham khảo ở sheet 'Phụ lục'.

Sheet Giới thiệu
B2: Test Cases — Server ↔ Gateway ↔ Node (IT & System Test)
B3: Hệ thống tưới tiêu thông minh: Node (firmware ESP32) ⟷ (LoRa UART) ⟷ Gateway (firmware ESP32) ⟷ (MQTT TLS) ⟷ Server.
B4: Tài liệu cung cấp bộ test case IT (integration) + System test với Input/Output chi tiết cho cả 2 tầng giao tiếp.
B6: Thành phần hệ thống
B7: Thành phần | C7: Firmware | D7: Cổng serial | E7: Giao tiếp
B8: Node | C8: node_irr | D8: UART dây LoRa | E8: LoRa UART 9600 baud
B9: Gateway | C9: gateway_irr | D9: COM10 | E9: LoRa UART + MQTT (TLS 8883)
B10: Server (mô phỏng) | C10: test/mqtt_server_sim.py | D10: — | E10: MQTT broker HiveMQ Cloud
B13: 0. Cách sử dụng tài liệu
B14: Mỗi test case có định dạng chuẩn:
B15: • Loại: IT (giữa 2 module) hoặc System (end-to-end cả 3 thành phần).
B16: • Tầng: Node↔GW, GW↔Server, hoặc End-to-end (Server→GW→Node→GW→Server).
B17: • Input: dữ liệu đưa vào chính xác — byte LoRa (hex) hoặc JSON MQTT.
B18: • Output mong đợi: byte/JSON/message + điều kiện PASS.
B19: • Verify: cách xác nhận (serial node / serial gateway / bảng nhận trên script mô phỏng server).
B21: Chuẩn bị môi trường (chạy 1 lần trước mọi nhóm)
B22: 1. Flash firmware Node (node_irr), mở serial monitor.
B23: 2. Flash firmware Gateway (gateway_irr), mở serial monitor (COM10).
B24: 3. Bật MQTT broker (HiveMQ Cloud theo config.c, TLS 8883).
B25: 4. Chạy script mô phỏng server:
... B30: Ghi chú: Log gateway tag GATEWAY, node tag MAIN/COMMANDS. Khi input không ghi cụ thể, giá trị sensor lấy theo thực tế.

Sheet Quy ước giao thức
B2: Quy ước byte gói tin & mã lệnh
B4: Uplink LoRa 8B (Node → Gateway)
B5: | node_id | type | flags | soil | temp(+40) | hum | battery | crc |
B6: • temp lệch +40: temp_byte = temperature + 40. VD 28°C → 0x44 (68).
B7: • crc = XOR của 7 byte trước (không bỏ 0x00).
B9: Downlink LoRa 6B (GW → Node)
B10: | node_id | 0x05 | cmd | param1 | param2 | crc |
B11: • crc = XOR của 5 byte trước.
B13: LoRa packet types (uplink)
B14: Mã (hex) | C14: Ý nghĩa
B15: 0x01 | C15: data
B16: 0x02 | C16: heartbeat
B17: 0x03 | C17: ACK
B18: 0x04 | C18: alarm
B19: 0x06 | C19: compact
B21: Flags (uplink)
B22: Bit (hex) | C22: Ý nghĩa
B23: 0x01 | C23: pump on
B24: 0x02 | C24: threshold_exceeded
B25: 0x04 | C25: GW_lost
B26: 0x08 | C26: sensor_ok
B28: Compact presence (bitmask)
B29: Bit (hex) | C29: Field
B30: 0x01 | C30: temp
B31: 0x02 | C31: hum
B32: 0x04 | C32: soil
B33: 0x08 | C33: battery
B34: 0x10 | C34: flags
B36: Command codes (downlink)
B37: Mã (hex) | C37: Lệnh
B38: 0x01 | C38: set_interval
B39: 0x02 | C39: on
B40: 0x03 | C40: off
B41: 0x04 | C41: set_threshold
B42: 0x05 | C42: set_schedule
B43: 0x06 | C43: report
B44: 0x07 | C44: toggle
B45: 0x08 | C45: set_mode
B46: 0x09 | C46: ACK rỗng/keep-alive
B47: 0x0A | C47: set_delta
...

Sheet MQTT Topics
B2: MQTT topics (site/gw mặc định HCM / gw_01)
B4: Hướng | C4: Topic | D4: Payload
B5: Node→Server | C5: irrigation/HCM/gw_01/node_01/data | D5: JSON sensor
B6: Node→Server | C6: irrigation/HCM/gw_01/node_01/status | D6: {"node":1,"status":"online/offline",...}
B7: Node→Server | C7: irrigation/HCM/gw_01/node_01/alarm | D7: JSON alarm
B8: GW→Server | C8: irrigation/HCM/gw_01/status | D8: JSON heartbeat
B9: Server→Node | C9: irrigation/HCM/gw_01/node_01/cmd | D9: JSON lệnh
B10: Server→GW | C10: irrigation/HCM/gw_01/config | D10: (chưa dùng — ngoài phạm vi)

Sheet Test Cases
A1: Nhóm | B1: Mã TC | C1: Tên Test Case | D1: Loại | E1: Tầng | F1: Tiền điều kiện | G1: Input | H1: Output mong đợi | I1: Điều kiện PASS | J1: Cách Verify | K1: Kết quả | L1: Người test | M1: Ngày test | N1: Ghi chú
A2: A | B2: TC-A01 | C2: Node cold boot — baseline data đầu tiên | D2: IT | E2: Node↔GW | F2: Node lần đầu cấp nguồn (RTC magic invalid); gateway + MQTT online. | G2: Cấp nguồn Node (không, cold boot / wake=UNDEFINED). | H2: Node: LED blink 3 lần; log 'Cold boot (first power-on)'. Vì lastSentTemp==INT8_MIN → node gửi baseline 0x01 đầy đủ (VD: 01 01 08 2E 44 41 55 <crc> — soil 46, temp 28, hum 65, bat 85, flags=0x08 sensor_ok). Gateway publish .../node_01/data JSON + trả downlink ACK rỗng 01 05 09 00 00 <crc>. Node log 'gatewayLostCount reset to 0 (valid downlink)'. | I2: (1) baseline 0x01 gửi lần đầu, (2) data JSON khớp node/soil/temp/hum/battery, (3) ACK rỗng về node trong window 350ms. | J2: Serial node + script nhận data.
A3: A | B3: TC-A02 | C3: Gateway boot — publish online ngay khi connect MQTT | D3: IT | E3: GW↔Server | F3: - | G3: Bật gateway. | H3: Ngay sau MQTT_EVENT_CONNECTED, gateway publish {"status":"online","version":"1.0.0"} và subscribe irrigation/HCM/gw_01/+/cmd. | I3: Script nhận online ngay sau khi gateway connect. | J3: Script listen MQTT.
A4: A | B4: TC-A03 | C4: Gateway heartbeat 60s định kỳ | D4: IT | E4: GW↔Server | F4: Gateway đã online. | G4: Chờ ≥130s, quan sát .../gw_01/status. | H4: Mỗi 60s publish {"status":"online","nodes_registered":2,"commands_cached":0,"uptime_seconds":<tăng>,"version":"1.0.0","site":"HCM","gateway_id":"gw_01"}. | I4: 2 heartbeat cách ~60s, uptime_seconds tăng, nodes_registered=2, commands_cached=0. | J4: Script nhận 2 message trong 130s.
A5: A | B5: TC-A04 | C5: LWT offline khi mất kết nối MQTT | D5: System | E5: GW↔Server | F5: Gateway đang online. | G5: Tắt broker (hoặc ngắt mạng gateway). | H5: Broker publish Last Will {"status":"offline"} lên .../gw_01/status. | I5: Script nhận offline trong < ~1 phút. | J5: Script listen MQTT. Note: LWT do broker xử lý; phụ thuộc broker có ghi nhận.
A6: B | B6: TC-B01 | C6: Data packet đầy đủ 0x01 → publish data JSON | D6: IT | E6: Node↔GW | F6: - | G6: Uplink 8B: 01 01 00 32 44 41 55 C9 (node=1, type=0x01, flags=0, soil=0x32(50), temp=0x44(68→28°C), hum=0x41(65), batt=0x55(85); crc=XOR=0xC9) | H6: .../node_01/data: {"node":1,"soil":50,"temp":28,"hum":65,"pump":0,"battery":85,"threshold_exceeded":false,"timestamp":"..."}. Gateway trả ACK rỗng downlink. | I6: Data JSON khớp + ACK rỗng gửi về. | J6: Script nhận data.
A7: B | B7: TC-B02 | C7: Compact 0x06 — merge giữ giá trị cũ khi field vắng | D7: IT | E7: Node↔GW | F7: Node có baseline (soil=50,temp=28,hum=65,bat=85). | G7: Compact chỉ thay đổi soil + flags, presence=0x10|0x04=0x14: 01 06 14 28 08 <crc> (soil=0x28(40), flags=0x08) | H7: Data JSON soil=40 (đổi), nhưng temp/hum/battery giữ giá trị cũ (28,65,85). Node đánh dấu ONLINE. | I7: Field vắng không bị reset. | J7: Script nhận soil=40,temp=28,hum=65,bat=85.
A8: B | B8: TC-B03 | C8: Heartbeat 0x02 — online + last_seen, KHÔNG publish data | D8: IT | E8: Node↔GW | F8: - | G8: 01 02 00 00 00 00 55 B8 (battery=0x55). | H8: Gateway node_mark_online + update last_seen; không publish data. Nếu node vừa offline → publish status online. Trả ACK rỗng để reset gatewayLostCount. | I8: Không có data mới; status chỉ publish khi node trước đó offline. | J8: GW log + script không nhận data mới.
A9: B | B9: TC-B04 | C9: Alarm 0x04 — cross-verify flags vs soil rồi publish alarm | D9: IT | E9: Node↔GW | F9: - | G9: Code sensor error (code=1) trong cả flags & soil: 01 04 01 01 00 00 FF FA (battery=0xFF; crc=XOR=0xFA) | H9: .../node_01/alarm: {"node":1,"alarm_code":1,"type":"alarm","message":"Sensor error — 3 consecutive sensor read failures","flags":1}. node_mark_online, last_seen update, không ghi đè soil/temp/hum/battery. ACK rỗng gửi về node (node không ACK lại alarm). | I9: Alarm JSON đúng + data không bị ghi đè. | J9: Script nhận alarm + kiểm tra data cũ không đổi.
A10: B | B10: TC-B05 | C10: Alarm mismatch flags vs soil — vẫn dùng flags | D10: IT | E10: Node↔GW | F10: - | G10: 01 04 03 05 00 00 FF <crc> (flags=0x03 relay error, soil=0x05 mismatch). | H10: GW log 'Alarm code mismatch: flags=0x03 soil=0x05, using flags'; publish alarm_code=3. | I10: alarm_code=3 trong MQTT. | J10: Script nhận alarm.
A11: C | B11: TC-C01 | C11: Schema data JSON chuẩn + threshold_exceeded=false | D11: IT | E11: GW↔Server | F11: - | G11: Uplink 0x01 với soil=50 (trong band 30–70). | H11: Data JSON đủ node,soil,temp,hum,pump,battery,timestamp,threshold_exceeded; threshold_exceeded=false, không có threshold_low/high. | I11: Schema đúng và threshold_exceeded=false. | J11: Script --verify (data schema).
A12: C | B12: TC-C02 | C12: Vượt threshold — data có flag + alarm | D12: IT | E12: GW↔Server | F12: - | G12: Soil=15 (ngoài low=30). | H12: Data: threshold_exceeded=true, kèm threshold_low=30,threshold_high=70. .../node_01/alarm: {"node":1,"type":"alarm","message":"Sensor alarm triggered","soil":15,"threshold_low":30,"threshold_high":70} | I12: Data + alarm đúng nội dung. | J12: Script suite C.
A13: C | B13: TC-C03 | C13: Node offline sau timeout 180s + status | D13: System | E13: GW↔Server | F13: Node từng online rồi dừng gửi. | G13: Chờ >180s không có uplink từ node. | H13: Sau 180s timeout (check 1s) gateway publish {"node":1,"status":"offline","timestamp":<epoch>}. | I13: Xuất hiện 1 message offline trong (180s,190s). | J13: Script listen MQTT theo thời gian.
... A46: G | B46: TC-G08 | C46: battery=0xFF (external power) | D46: Negative | E46: Edge case | F46: - | G46: Data battery=0xFF. | H46: Gw publish battery:255. Không alarm low-battery. | I46: battery=255 trong JSON, không có cảnh báo pin yếu. | J46: Script nhận data.

Sheet Phụ lục
B2: Phụ lục — Cách verify / kết quả mong đợi
B4: Loại | C4: Cách | D4: Tool
B5: byte-level LoRa | C5: serial monitor gateway + node | D5: idf.py monitor
B6: MQTT payload | C6: script listen (-l) | D6: mqtt_server_sim.py
B7: MQTT suite + report | C7: --suite file.json → PASS/FAIL | D7: mqtt_server_sim.py
B8: trạng thái | C8: nodes_registered / commands_cached / uptime | D8: script
B11: CRC8 (XOR) tính vài mẫu:
B12: Hex bytes (trước CRC) | C12: CRC
B13: 01 05 04 14 50 | C13: 0x44
B14: 01 05 01 2C 01 | C14: 0x42
B15: 01 04 01 01 00 00 FF | C15: 0xFA
B16: 01 05 02 3C 00 | C16: 0x3A
B17: 01 01 00 32 44 41 55 | C17: 0xC9
B19: (Tự kiểm tra bằng hàm crc8_calculate trong gateway_irr/main/crc.c.)
B20: Nhiệt độ: luôn dùng wire byte (nhiệt độ + 40) khi khai báo input.
